Workbook

Sheet Country Overview
C1: Regulated | D1: Regulated/ if fitted
C2: Mandatory | D2: Mandatory fitment
C3: in drafting | D3: Pending document (Regulation under drafting stage)
C4: - | D4: Not Regulated/ to be considered
E5: GLOBAL | F5: ​Europe | AY5: North America | BB5: South America | CI5: Asia & Pacific | CN5: ASEAN | DX5: ​CIS (Commonwealth of Independent States) & EAEU (Eurasion Economic Union) | EJ5: Africa | GC5: Arab States
A6: Vehicle Category | B6: Category | C6: Acronym/ Scope | D6: Regulated Functions | E6: UN 1958 Agreement (UN Regulation 0 Whole Vehicle Type Approval) | F6: Main countries European Union (Germany, France,..) Swiss UK Turkey (Israel) | G6: Switzerland | H6: United Kingdom | I6: Turkey | J6: Israel | K6: Germany | L6: Andorra | M6: Austria | N6: Albania | O6: Belgium | P6: Bosnia and Herzegovina | Q6: Bulgaria | R6: Croatia | S6: Cyprus | T6: Czech Republic | U6: Denmark | V6: Estonia | W6: Finland | X6: France | Y6: Georgia | Z6: Greece | AA6: Hungary | AB6: Iceland | AC6: Ireland | AD6: Italy | AE6: Latvia | AF6: Liechtenstein | AG6: Lithuania | AH6: Luxembourg | AI6: Malta | AJ6: Monaco | AK6: Montenegro | AL6: Netherlands | AM6: Norway | AN6: Poland | AO6: Portugal | AP6: Romania | AQ6: San Marino | AR6: Serbia | AS6: Slovakia | AT6: Slovenia | AU6: Spain | AV6: Sweden | AW6: The Former Yugoslav Rep. of Macedonia | AX6: Vatican | AY6: Main countries USA (displayed) Canada partly applies UN] | AZ6: United States | BA6: Canada | BB6: Main countries Brazil Mexico (UN and FMVSS) | BC6: Brazil | BD6: Colombia UN 1958 agreement member (in application process) | BE6: Mexico | BF6: Antigua and Barbuda | BG6: Bahamas | BH6: Barbados | BI6: Belize | BJ6: Bolivia (Plurinational State of) | BK6: Chile | BL6: Costa Rica | BM6: Cuba | BN6: Dominica | BO6: Dominican Rep. | BP6: Ecuador | BQ6: El Salvador | BR6: Grenada | BS6: Guatemala | BT6: Guyana | BU6: Haiti | BV6: Honduras | BW6: Jamaica | BX6: Nicaragua | BY6: Panama | BZ6: Paraguay | CA6: Peru | CB6: Saint Kitts and Nevis | CC6: Saint Lucia | CD6: Saint Vincent and the Grenadines | CE6: Suriname | CF6: Trinidad and Tobago | CG6: Uruguay | CH6: Venezuela | CI6: China | CJ6: Hong Kong (China) | CK6: India | CL6: Japan (UN 1958) | CM6: Korea (Rep. of) (UN 1958) | CN6: Main countries Indonesia Thailand (UN 1958) Philippines Malaysia (UN 1958) | CO6: Taiwan (China) | CP6: Thailand | CQ6: Indonesia | CR6: Malaysia | CS6: Philippines | CT6: Singapore | CU6: Afghanistan | CV6: Bangladesh | CW6: Bhutan | CX6: Brunei Darussalam | CY6: Cambodia | CZ6: Fiji | DA6: Iran (Islamic Republic of) | DB6: Kiribati | DC6: Lao P.D.R. | DD6: Macau (China) | DE6: Maldives | DF6: Marshall Islands | DG6: Micronesia | DH6: Mongolia | DI6: Myanmar | DJ6: Nauru | DK6: Nepal (Republic of) | DL6: New Zealand | DM6: Pakistan | DN6: Papua New Guinea | DO6: Samoa | DP6: Solomon Islands | DQ6: Sri Lanka | DR6: Timor-Leste | DS6: Tonga | DT6: Tuvalu | DU6: Vanuatu | DV6: Viet Nam | DW6: Australia (UN 1958) AU_ADR_Harmonisation_EN_2022-04-04 (1).pdf | DX6: Main countires EAEU Russia (UN 1958) Ukraine | DY6: Armenia | DZ6: Azerbaijan | EA6: Belarus | EB6: Kazakhstan | EC6: Kyrgyzstan | ED6: Moldova | EE6: Russian Federation | EF6: Tajikistan | EG6: Turkmenistan | EH6: Ukraine | EI6: Uzbekistan | EJ6: Main countries South Africa (UN 1958) Namibia Nigeria | EK6: South Africa | EL6: Namibia | EM6: Nigeria | EN6: Angola | EO6: Benin | EP6: Botswana | EQ6: Burkina Faso | ER6: Burundi | ES6: Cameroon | ET6: Cabo Verde | EU6: Central African Rep. | EV6: Chad | EW6: Congo (Rep. of the) | EX6: Côte d'Ivoire | EY6: Dem. Rep. of the Congo) | EZ6: Equatorial Guinea | FA6: Eritrea | FB6: Eswatini | FC6: Ethiopia | FD6: Gabon | FE6: Gambia | FF6: Ghana | FG6: Guinea | FH6: Guinea-Bissau | FI6: Kenya | FJ6: Lesotho | FK6: Liberia | FL6: Madagascar | FM6: Malawi | FN6: Mali | FO6: Mauritius | FP6: Mozambique | FQ6: Niger | FR6: Rwanda | FS6: Sao Tome and Principe | FT6: Senegal | FU6: Seychelles | FV6: Sierra Leone | FW6: South Sudan | FX6: Tanzania | FY6: Togo | FZ6: Uganda | GA6: Zambia | GB6: Zimbabwe | GC6: Main countries Egypt (UN 1958) Saudi Arabia Oman Morocco Lebanon | GD6: Egypt | GE6: Saudi Arabia | GF6: Oman | GG6: Morocco | GH6: Lebanon | GI6: Jordan | GJ6: Algeria | GK6: Bahrain | GL6: Comoros | GM6: Djibouti | GN6: Iraq | GO6: Kuwait | GP6: Libya | GQ6: Mauritania | GR6: Qatar | GS6: Somalia | GT6: Sudan | GU6: Syrian Arab Republic | GV6: Tunisia | GW6: United Arab Emirates | GX6: Yemen | GY6: United Arab Emirates | GZ6: Yemen
B7: Framework Regulation (defining mandatory systems) | E7: UN Regulation No. 0 | F7: (EU) 2019/2144 | AY7: FMVSS CMVSS | BC7: BR_Decree_9557-2018_Rota_2030_EN_2019-03-04 (1).pdf | BD7: CO_Res_20223040044585-2022_EN_2025-10-09.pdf | BE7: MX_NOM-194-SE-2021_EN_2023-04-14.pdf | CK7: CMVR
BC8: BR_Port_SENATRAN_1554-2022_EN_2023-01-17.pdf
B9: CATEGORY M1 & N1
A10: M1 & N1 | B10: Warning/ emergency / Assisting features level 0-1
B11: Generic Regulations | D11: Framework regulations/ Type Approvals/ General Safety Regulations | CM11: KR_KMVSS_complete_corr_EN_2022-02-15.pdf
B12: Long. Control | C12: AEB | D12: Advanced Emergency Braking (includes FCW) | E12: UN R152 | F12: UN R152 | G12: Mandatory | H12: Mandatory | I12: Mandatory | J12: Mandatory | AY12: FMVSS 127 Mandatory by 2029 | AZ12: FMVSS 127 | BA12: - | BB12: UN R152 | BC12: UN R152 | BD12: UN R152 mandatory by 08/2027 all models by 08/2029 | BE12: UN R152 | CI12: !! GB/T 39901 (in process of being made mandatory with updated requirements 2028 (only for M1) | CK12: Regulated (2026) AIS-185 (M1 & N1) | CL12: UN R152 | CM12: KMVSS Article 90-3 M1/N1 = UN R152 | CN12: UN R152 | DW12: UN R152/ ADR98 | DX12: =E12 -> UN R152 | EJ12: =E12 -> UN R152 | GC12: =E12 -> UN R152
C13: AEB VRU | D13: Advanced Emergency Braking for VRU (pedestrian & Cyclists) | E13: UN R152 | F13: UN R152 | G13: Mandatory | H13: Mandatory | I13: Mandatory | J13: Mandatory | AY13: FMVSS 127 Mandatory by 2029 | AZ13: FMVSS 127 | BA13: - | BB13: UN R152 (pedestrians) | BC13: UN R152 (pedestrians) | BD13: UN R152 mandatory by 08/2027 all models by 08/2029 | BE13: UN R152 | CI13: in drafting | CK13: Regulated (2026) AIS-185 (M1 & N1) | CL13: UN R152 | CM13: KMVSS Article 90-3 M1/N1 = UN R152 | CN13: UN R152 | DW13: UN R152/ ADR98 | DX13: =E13 -> UN R152 | EJ13: =E13 -> UN R152 | GC13: =E13 -> UN R152
C14: R-AEB | D14: Rear Advanced Emergency Braking | E14: - | F14: UN R13H (M1) | AY14: - | AZ14: NCAP | BA14: - | BB14: - | BC14: - | BD14: - | BE14: - | CI14: GB 21670-2008 | CK14: IS 15986-2015 AIS-151 | CL14: - | CM14: - | CN14: - | DW14: =E14 -> - | DX14: =E14 -> - | EJ14: =E14 -> - | GC14: =E14 -> -
C15: TSR (ISA) | D15: Traffic Sign Recognition (Intelligent Speed Assistance) | E15: - | F15: (EU) 2021/1958 | G15: (EU) 2021/1958 | H15: - | I15: (EU) 2021/1958 | J15: EU 2021/1958 + Israel Catalogue Israeli Catalog of Road Signs 2022.pdf | K15: Mandatory | L15: Mandatory | M15: Mandatory | N15: Mandatory | O15: Mandatory | Q15: Mandatory | R15: Mandatory | S15: Mandatory | T15: Mandatory | U15: Mandatory | V15: Mandatory | W15: Mandatory | X15: Mandatory | Y15: Mandatory | Z15: Mandatory | AA15: Mandatory | AB15: Mandatory | AC15: Mandatory | AD15: Mandatory | AE15: Mandatory | AF15: Mandatory | AG15: Mandatory | AH15: Mandatory | AI15: Mandatory | AJ15: Mandatory | AK15: Mandatory | AL15: Mandatory | AM15: Mandatory | AN15: Mandatory | AO15: Mandatory | AP15: Mandatory | AQ15: Mandatory | AR15: - | AS15: Mandatory | AT15: Mandatory | AU15: Mandatory | AV15: Mandatory | AW15: Mandatory | AX15: Mandatory | AY15: - | AZ15: - | BA15: - | BB15: - | BD15: - | BE15: - | CI15: GB/T 44433-2024 | CK15: - | CL15: - | CM15: - | CN15: - | DW15: =E15 -> - | DX15: =E15 -> - | EJ15: =E15 -> - | EK15: =R15 -> Mandatory | EL15: =S15 -> Mandatory | EM15: =T15 -> Mandatory | EN15: =U15 -> Mandatory | EO15: =V15 -> Mandatory | EP15: =W15 -> Mandatory | EQ15: =X15 -> Mandatory | ER15: =Y15 -> Mandatory | ... FU15: =BB15 -> - | FV15: =BC25 -> Res. CONTRAN 970/2022 | FW15: =BD15 -> - | FX15: =BE15 -> - | FY15: =BF15 -> 0 | FZ15: =BG15 -> 0 | GA15: =BH15 -> 0 | GB15: =BI15 -> 0 | GC15: =E15 -> -
C16: ACC | D16: Adaptive Cruise Control | E16: UN R13H ANNEX 8 (General Safety Assessment) | F16: UN R13H ANNEX 8 (General Safety Assessment) | AY16: - | AZ16: - | BA16: - | BB16: - | BF16: NCAP | BG16: NCAP | BH16: NCAP | BI16: NCAP | BJ16: NCAP | BK16: NCAP | BL16: NCAP | BM16: NCAP | BN16: NCAP | BO16: NCAP | BP16: NCAP | BQ16: NCAP | BR16: NCAP | BS16: NCAP | BT16: NCAP | BU16: NCAP | BV16: NCAP | BW16: NCAP | BX16: NCAP | BY16: NCAP | BZ16: NCAP | CA16: NCAP | CB16: NCAP | CC16: NCAP | CD16: NCAP | CE16: NCAP | CF16: NCAP | CG16: NCAP | CH16: NCAP | CI16: GB/T 20608-2006 GB 21670-2008 Annex D | CJ16: NCAP | CK16: - | CL16: UN R13H ANNEX 8 | CM16: UN R13H ANNEX 8 | CN16: UN R13H ANNEX 8 | CO16: NCAP | CP16: NCAP | CQ16: NCAP | CR16: NCAP | CS16: NCAP | CT16: NCAP | CU16: NCAP | CV16: NCAP | CW16: NCAP | CX16: NCAP | CY16: NCAP | CZ16: NCAP | DA16: NCAP | DB16: NCAP | DC16: NCAP | DD16: NCAP | DE16: NCAP | DF16: NCAP | DG16: NCAP | DH16: NCAP | DI16: NCAP | DJ16: NCAP | DK16: NCAP | DL16: NCAP | DM16: NCAP | DN16: NCAP | DO16: NCAP | DP16: NCAP | DQ16: NCAP | DR16: NCAP | DS16: NCAP | DT16: NCAP | DU16: NCAP | DV16: NCAP | DW16: =E16 -> UN R13H ANNEX 8 (General Safety Assessment) | DX16: =E16 -> UN R13H ANNEX 8 (General Safety Assessment) | EJ16: =E16 -> UN R13H ANNEX 8 (General Safety Assessment) | EK16: NCAP | EL16: NCAP | EM16: NCAP | EN16: NCAP | EO16: NCAP | EP16: NCAP | EQ16: NCAP | ER16: NCAP | ES16: NCAP | ET16: NCAP | EU16: NCAP | EV16: NCAP | EW16: NCAP | EX16: NCAP | EY16: NCAP | EZ16: NCAP | FA16: NCAP | FB16: NCAP | FC16: NCAP | FD16: NCAP | FE16: NCAP | FF16: NCAP | FG16: NCAP | FH16: NCAP | FI16: NCAP | FJ16: NCAP | FK16: NCAP | FL16: NCAP | FM16: NCAP | FN16: NCAP | FO16: NCAP | FP16: NCAP | FQ16: NCAP | FR16: NCAP | FS16: NCAP | FT16: NCAP | FU16: NCAP | FV16: NCAP | FW16: NCAP | FX16: NCAP | FY16: NCAP | FZ16: NCAP | GA16: NCAP | GB16: NCAP | GC16: =E16 -> UN R13H ANNEX 8 (General Safety Assessment)
C17: ACPE | D17: Acceleration Control for Pedal Error | E17: UN R175 | F17: UN R175 | G17: in drafting | H17: in drafting | I17: in drafting | J17: in drafting | AY17: - | AZ17: - | BA17: - | BB17: - | BC17: - | BD17: - | BE17: - | CI17: - | CK17: - | CL17: UN R175 | CM17: UN R175 | CN17: UN R175 | DW17: UN R175 | DX17: UN R175 | DY17: UN R175 | DZ17: UN R175 | EA17: UN R175 | EB17: UN R175 | EC17: UN R175 | ED17: UN R175 | EE17: UN R175 | EF17: UN R175 | EG17: UN R175 | EH17: UN R175 | EI17: UN R175 | EJ17: UN R175 | EK17: UN R175 | EL17: UN R175 | EM17: UN R175 | EN17: UN R175 | EO17: UN R175 | EP17: UN R175 | EQ17: UN R175 | ER17: UN R175 | ES17: UN R175 | ET17: UN R175 | EU17: UN R175 | EV17: UN R175 | EW17: UN R175 | EX17: UN R175 | EY17: UN R175 | EZ17: UN R175 | FA17: UN R175 | FB17: UN R175 | FC17: UN R175 | FD17: UN R175 | FE17: UN R175 | FF17: UN R175 | FG17: UN R175 | FH17: UN R175 | FI17: UN R175 | FJ17: UN R175 | FK17: UN R175 | FL17: UN R175 | FM17: UN R175 | FN17: UN R175 | FO17: UN R175 | FP17: UN R175 | FQ17: UN R175 | FR17: UN R175 | FS17: UN R175 | FT17: UN R175 | FU17: UN R175 | FV17: UN R175 | FW17: UN R175 | FX17: UN R175 | FY17: UN R175 | FZ17: UN R175 | GA17: UN R175 | GB17: UN R175 | GC17: UN R175
B18: Lateral Control/ ACSF | C18: LDWS | D18: Lane Departure Warning System | E18: UN R130 | F18: UN R130 | G18: Regulated | H18: Regulated | I18: Regulated | J18: Regulated | AY18: - | AZ18: - | BA18: - | BB18: UN R130 | BC18: UN R130 ISO 17361:2017 | BE18: UN R130 | CI18: GB/T 26773-2011 | CK18: in drafting AIS-188 | CL18: UN R130 | CM18: UN R130 | CN18: =E18 -> UN R130 | DW18: UN R130/ ADR 99 | DX18: =E18 -> UN R130 | EJ18: =E18 -> UN R130 | GC18: =E18 -> UN R130
C19: LKA | D19: Lane Keeping Assist | E19: UN R79 ACSF B1 | F19: UN R79 ACSF B1 | G19: Regulated | H19: Regulated | I19: Regulated | J19: Regulated | AY19: - | AZ19: - | BA19: - | BB19: UN R79 ACSF B1 | BC19: UN R79 ACSF B1 | BE19: UN R79 ACSF B1 | CI19: GB/T 39323-2020 | CK19: AIS 193 | CL19: UN R79 ACSF B1 | CM19: UN R79 ACSF B1 | CN19: =E19 -> UN R79 ACSF B1 | CO19: VSTD 47-2 (472) == UNR 79 | DX19: =E19 -> UN R79 ACSF B1 | EJ19: =E19 -> UN R79 ACSF B1 | GC19: =E19 -> UN R79 ACSF B1
C20: ELKS | D20: Emergency Lane Keeping System (based on lane detection) | E20: UN R in drafting (based on EU regulation) | F20: (EU) 2021/646 ELKS | G20: Mandatory | H20: Mandatory | I20: Mandatory | J20: Mandatory | AY20: - | AZ20: - | BA20: - | BB20: - | BC20: Regulated | CI20: - | CK20: in drafting AIS 191 Part1 (M1) | CL20: - | CM20: - | CN20: - | DW20: ADR 107/00 = (EU) 2021/646 ELKS | DX20: - | DY20: - | DZ20: - | EA20: - | EB20: - | EC20: - | ED20: - | EE20: - | EF20: - | EG20: - | EH20: - | EI20: - | EJ20: - | EK20: - | EL20: - | EM20: - | EN20: - | EO20: - | EP20: - | EQ20: - | ER20: - | ES20: - | ET20: - | EU20: - | EV20: - | EW20: - | EX20: - | EY20: - | EZ20: - | FA20: - | FB20: - | FC20: - | FD20: - | FE20: - | FF20: - | FG20: - | FH20: - | FI20: - | FJ20: - | FK20: - | FL20: - | FM20: - | FN20: - | FO20: - | FP20: - | FQ20: - | FR20: - | FS20: - | FT20: - | FU20: - | FV20: - | FW20: - | FX20: - | FY20: - | FZ20: - | GA20: - | GB20: - | GC20: -
C21: ESF | D21: Emergency Steering Function (object evasion) | E21: UN R79 ESF | F21: UN R79 ESF | AY21: - | AZ21: - | BA21: - | BB21: - | CI21: - | CL21: UN R79 ESF | CM21: UN R79 ESF | CN21: =E21 -> UN R79 ESF | CO21: VSTD 47-2 (472) == UNR 79 | DW21: UN R79 ESF | DX21: =E21 -> UN R79 ESF | EJ21: =E21 -> UN R79 ESF | GC21: =E21 -> UN R79 ESF
C22: Parking | D22: Assisted Parking (only Steering) | E22: UN R79 ACSF Cat A | F22: UN R79 ACSF Cat A | G22: Regulated | H22: Regulated | I22: Regulated | J22: Regulated | AY22: - | AZ22: - | BA22: - | BB22: - | BC22: Regulated | CI22: - | CK22: - | CL22: UN R79 ACSF Cat A | CM22: UN R79 ACSF Cat A | CN22: =E22 -> UN R79 ACSF Cat A | CO22: VSTD 47-2 (472) == UNR 79 | DW22: =E22 -> UN R79 ACSF Cat A | DX22: =E22 -> UN R79 ACSF Cat A | EJ22: =E22 -> UN R79 ACSF Cat A | GC22: =E22 -> UN R79 ACSF Cat A
C23: Lateral Control/ ACSF | D23: Lane Change Assist | E23: UN R79 ACSF Cat C | F23: UN R79 ACSF Cat C | G23: Regulated | H23: Regulated | I23: Regulated | J23: Regulated | AY23: - | AZ23: - | BA23: - | BB23: - | CI23: - | CK23: - | CL23: UN R79 ACSF Cat C | CM23: UN R79 ACSF Cat C | CN23: =E23 -> UN R79 ACSF Cat C | CO23: VSTD 47-2 (472) == UNR 79 | DW23: =E23 -> UN R79 ACSF Cat C | DX23: =E23 -> UN R79 ACSF Cat C | EJ23: =E23 -> UN R79 ACSF Cat C | GC23: =E23 -> UN R79 ACSF Cat C
D24: Risk Mitigation Function | E24: UN R79 RMF | F24: UN R79 RMF | AY24: - | AZ24: - | BA24: - | BB24: - | CI24: - | CK24: - | CL24: UN R79 RMF | CM24: UN R79 RMF | CN24: =E24 -> UN R79 RMF | DW24: =E24 -> UN R79 RMF | DX24: =E24 -> UN R79 RMF | EJ24: =E24 -> UN R79 RMF | GC24: =E24 -> UN R79 RMF
B25: Visibility | D25: Adaptive Lighting | E25: UN R48 | F25: UN R48 | G25: Regulated | H25: Regulated | I25: Regulated | J25: Regulated | AY25: FMVSS 108 | AZ25: FMVSS 108 | BA25: - | BB25: Res. CONTRAN 970/2022 | BC25: Res. CONTRAN 970/2022 | CI25: - | CK25: in drafting AIS-008 Rev2 | CL25: UN R48 | CM25: UN R48 | CN25: =E25 -> UN R48 | CO25: VSTD 3-5 (035) == UNR 48 | DW25: UN R48/ ADR 45/01 | DX25: =E25 -> UN R48 | EJ25: =E25 -> UN R48 | GC25: =E25 -> UN R48
B26: VRU Close Proximity Detection/Visibility | D26: VRU Rear (View / Detection) | E26: UN R158 | F26: UN R158 | G26: Mandatory | H26: Mandatory | I26: Mandatory | J26: Mandatory | L26: 158 | AY26: FMVSS 111 (Visibility Only) | AZ26: Mandatory | BA26: - | BB26: Resolution CONTRAN 759/2018 | BC26: Resolution CONTRAN 759/2018 | CI26: in drafting ~2027? | CK26: AIS-145 | CL26: UN R158 MLIT 619 Att 129 MLIT 619 Att 130 | CM26: UN R158 | CN26: =E26 -> UN R158 | DW26: UN R158 (ADR 108) | DX26: =E26 -> UN R158 | EJ26: =E26 -> UN R158 | GC26: =E26 -> UN R158
D27: VRU Front & Nearside (View / Detection) | E27: UN R166 | F27: UN R166 | G27: Regulated | H27: Regulated | I27: Regulated | J27: Regulated | L27: 166 | AY27: - | AZ27: - | BA27: - | BB27: - | BC27: - | CI27: - | CK27: - | CL27: UN R166 | CM27: UN R166 | CN27: =E27 -> UN R166 | DW27: =E27 -> UN R166 | DX27: =E27 -> UN R166 | EJ27: =E27 -> UN R166 | GC27: =E27 -> UN R166
D28: Blind Spot Information System | E28: - | F28: - | G28: Mandatory* | H28: Mandatory* | I28: Mandatory* | J28: Mandatory* | AY28: - | AZ28: - | BA28: - | BB28: - | BC28: - | CI28: GB/T 39265-2020 | CK28: - | CL28: - | CM28: - | CN28: - | DW28: - | DX28: - | EJ28: - | GC28: -
D29: Moving Off Information System | E29: - | F29: - | G29: Mandatory* | H29: Mandatory* | I29: Mandatory* | J29: Mandatory* | AY29: - | AZ29: - | BA29: - | BB29: - | BC29: - | CI29: - | CK29: - | CL29: - | CM29: - | CN29: - | DW29: - | DX29: - | EJ29: - | GC29: -
C30: IVD/ CMS | D30: Indirect Vision Devices/ Camera Monitoring System | E30: UN R46 | F30: UN R46 | G30: Regulated | H30: Regulated | I30: Regulated | J30: Regulated | AY30: - | AZ30: in drafting ? | BA30: - | BB30: - | BC30: - | CI30: GB 15084-2022 | CK30: AIS-001 Part 1 AIS-002 Part 1 | CL30: UN R46 | CM30: UN R46 | CN30: =E30 -> UN R46 | CO30: VSTD 23-2 (232) VSTD 27-1 (271) == UNR 46 | DW30: =E30 -> UN R46 | DX30: =E30 -> UN R46 | EJ30: =E30 -> UN R46 | GC30: =E30 -> UN R46
B31: Driver/ Occupant Monitoring | C31: DDAW | D31: Driver Drowsiness and Attention Warning | E31: UN R in drafting (based on EU regulation) | F31: (EU) 2021/1341 | G31: Mandatory | H31: Mandatory | I31: Mandatory | J31: Mandatory | AY31: drafting | AZ31: - | BA31: - | BC31: - | CI31: - | CK31: Regulated (2025) AIS-184 (M, N2 & N3) | CL31: - | CM31: - | CN31: =E31 -> UN R in drafting (based on EU regulation) | DW31: =E31 -> UN R in drafting (based on EU regulation) | DX31: =E31 -> UN R in drafting (based on EU regulation) | EJ31: =E31 -> UN R in drafting (based on EU regulation) | GC31: =E31 -> UN R in drafting (based on EU regulation)
C32: ADDW | D32: Advanced Driver Distraction Warning | E32: - | F32: (EU) 2023/2590 | G32: Mandatory | H32: Mandatory | I32: Mandatory | J32: Mandatory | AY32: - | AZ32: - | BA32: - | BB32: - | BC32: - | CI32: - | CK32: - | CL32: - | CM32: - | CN32: =E32 -> - | DW32: =E32 -> - | DX32: =E32 -> - | EJ32: =E32 -> - | GC32: =E32 -> -
C33: AIIF | D33: Alcohol Interlock Installation Facility | E33: - | F33: (EU) 2021/1243 | G33: Mandatory | H33: Mandatory | I33: Mandatory | J33: Mandatory | AY33: Mandatory? | AZ33: Mandatory? | BA33: - | BC33: - | CI33: - | CK33: - | CL33: - | CM33: - | CN33: - | CO33: - | CP33: - | CQ33: - | CR33: - | CS33: - | CT33: - | CU33: - | CV33: - | CW33: - | CX33: - | CY33: - | CZ33: - | DA33: - | DB33: - | DC33: - | DD33: - | DE33: - | DF33: - | DG33: - | DH33: - | DI33: - | DJ33: - | DK33: - | DL33: - | DM33: - | DN33: - | DO33: - | DP33: - | DQ33: - | DR33: - | DS33: - | DT33: - | DU33: - | DV33: - | DW33: - | DX33: - | DY33: - | DZ33: - | EA33: - | EB33: - | EC33: - | ED33: - | EE33: - | EF33: - | EG33: - | EH33: - | EI33: - | EJ33: - | EK33: - | EL33: - | EM33: - | EN33: - | EO33: - | EP33: - | EQ33: - | ER33: - | ES33: - | ET33: - | EU33: - | EV33: - | EW33: - | EX33: - | EY33: - | EZ33: - | FA33: - | FB33: - | FC33: - | FD33: - | FE33: - | FF33: - | FG33: - | FH33: - | FI33: - | FJ33: - | FK33: - | FL33: - | FM33: - | FN33: - | FO33: - | FP33: - | FQ33: - | FR33: - | FS33: - | FT33: - | FU33: - | FV33: - | FW33: - | FX33: - | FY33: - | FZ33: - | GA33: - | GB33: - | GC33: -
C34: DOW | D34: Door Operning Warning | E34: - | F34: - | G34: - | H34: - | I34: - | J34: - | K34: - | L34: - | M34: - | N34: - | O34: - | P34: - | Q34: - | R34: - | S34: - | T34: - | U34: - | V34: - | W34: - | X34: - | Y34: - | Z34: - | AA34: - | AB34: - | AC34: - | AD34: - | AE34: - | AF34: - | AG34: - | AH34: - | AI34: - | AJ34: - | AK34: - | AL34: - | AM34: - | AN34: - | AO34: - | AP34: - | AQ34: - | AR34: - | AS34: - | AT34: - | AU34: - | AV34: - | AW34: - | AX34: - | AY34: - | AZ34: - | BA34: - | BB34: - | BC34: - | CI34: CN_GB_T_44173-2024_EN_2024-09-18.pdf | CK34: - | CL34: - | CM34: - | CN34: - | CO34: - | CP34: - | CQ34: - | CR34: - | CS34: - | CT34: - | CU34: - | CV34: - | CW34: - | CX34: - | CY34: - | CZ34: - | DA34: - | DB34: - | DC34: - | DD34: - | DE34: - | DF34: - | DG34: - | DH34: - | DI34: - | DJ34: - | DK34: - | DL34: - | DM34: - | DN34: - | DO34: - | DP34: - | DQ34: - | DR34: - | DS34: - | DT34: - | DU34: - | DV34: - | DW34: - | DX34: - | DY34: - | DZ34: - | EA34: - | EB34: - | EC34: - | ED34: - | EE34: - | EF34: - | EG34: - | EH34: - | EI34: - | EJ34: - | EK34: - | EL34: - | EM34: - | EN34: - | EO34: - | EP34: - | EQ34: - | ER34: - | ES34: - | ET34: - | EU34: - | EV34: - | EW34: - | EX34: - | EY34: - | EZ34: - | FA34: - | FB34: - | FC34: - | FD34: - | FE34: - | FF34: - | FG34: - | FH34: - | FI34: - | FJ34: - | FK34: - | FL34: - | FM34: - | FN34: - | FO34: - | FP34: - | FQ34: - | FR34: - | FS34: - | FT34: - | FU34: - | FV34: - | FW34: - | FX34: - | FY34: - | FZ34: - | GA34: - | GB34: - | GC34: -
B35: Driver/ Occupant Monitoring | C35: DDAW | D35: Driver Drowsiness and Attention Warning | E35: - | F35: (EU) 2021/1341 | G35: Mandatory | H35: Mandatory | I35: Mandatory | J35: Mandatory | AY35: drafting | AZ35: - | BC35: - | CI35: - | CK35: Regulated (2025) AIS-184 (M, N2 & N3) | CL35: - | CM35: - | CN35: =E35 -> - | DW35: =E35 -> - | DX35: =E35 -> - | EJ35: =E35 -> - | GC35: =E35 -> -
C36: ADDW | D36: Advanced Driver Distraction Warning | E36: - | F36: (EU) 2023/2590 | G36: Mandatory | H36: Mandatory | I36: Mandatory | J36: Mandatory | AY36: - | AZ36: - | BB36: - | BC36: - | CI36: - | CK36: - | CL36: - | CM36: - | CN36: =E36 -> - | DW36: =E36 -> - | DX36: =E36 -> - | EJ36: =E36 -> - | GC36: =E36 -> -
C37: AIIF | D37: Alcohol Interlock Installation Facility | E37: - | F37: (EU) 2021/1243 | G37: Mandatory | H37: Mandatory | I37: Mandatory | J37: Mandatory | AY37: Mandatory? | AZ37: Mandatory? | BC37: - | CI37: - | CK37: - | CL37: - | CM37: - | CN37: =E37 -> - | DW37: =E37 -> - | DX37: =E37 -> - | EJ37: =E37 -> - | GC37: =E37 -> -
B38: Vehicle Data | C38: EDR | D38: Event Data Recorder | E38: UN R160 | F38: UN R160 | G38: Mandatory | H38: Mandatory | I38: Mandatory | J38: Mandatory | AY38: - | AZ38: - | BB38: - | BC38: - | CI38: GB 39732-2020 (M1) | CK38: in drafting AIS-192 (M1) | CL38: UN R160 | CM38: UN R160 | CN38: =E38 -> UN R160 | CO38: VSTD 98 (980) == UNR | DW38: =E38 -> UN R160 | DX38: =E38 -> UN R160 | EJ38: =E38 -> UN R160 | GC38: =E38 -> UN R160
C39: DSSAD | D39: Data Storage Systems for Automated Driving | E39: part of UN R157/ VMAD | F39: part of UN R157/ VMAD | G39: Regulated | H39: Regulated | I39: Regulated | J39: Regulated | AY39: - | AZ39: - | BB39: - | BC39: - | CI39: - | CK39: - | CL39: part of UN R157/ VMAD | CM39: part of UN R157/ VMAD | CN39: =E39 -> part of UN R157/ VMAD | DW39: =E39 -> part of UN R157/ VMAD | DX39: =E39 -> part of UN R157/ VMAD | EJ39: =E39 -> part of UN R157/ VMAD | GC39: =E39 -> part of UN R157/ VMAD
B40: Transversal | C40: SW | D40: Software Updates | E40: UN R156 | F40: UN R156 | G40: Mandatory | H40: Mandatory | I40: Mandatory | J40: Mandatory | AY40: - | AZ40: - | BA40: ? | BC40: - | CK40: in drafting AIS-190 | CL40: UN R156 | CM40: UN R156 | CN40: =E40 -> UN R156 | CO40: VSTD 98 (970) == UNR | DW40: UN R156 | DX40: =E40 -> UN R156 | EJ40: =E40 -> UN R156 | GC40: =E40 -> UN R156
...

Sheet MAPPING with Deliverables
A2: Absolute Number | B2: GSR marker | C2: Category | D2: Platform | E2: Market | F2: aClassification | G2: aApplicability | H2: Coverage Review | I2: Coverage Review Comment | J2: Scope or Acronym | K2: Object_Title&Text | L2: Subtitle | M2: Description | N2: Revision | O2: Date of application | P2: Vehicle Category | Q2: Module name | R2: Link | S2: Valeo Standard/ Process Reference | T2: Evidence (Engineering Gate Deliverable) | U2: Reference to Eng. Gate | V2: Compliance Guide | W2: Compliance Guide Comment | X2: Certification/ Type Approval required
A3: 7 | B3: Undefined | K3: 1 Purpose/ Scope
A4: 2 | B4: Undefined | K4: This module serves as a database containing norms and regulations which are to be applied or are to be considered for the development of CDV products.
A5: 15 | B5: Undefined | K5: 2 General Definitions
A6: 18 | B6: Undefined | K6: Norms and Regulations are hereby addressed as document.
A7: 28 | B7: Undefined | K7: 2.1 Attributes
A8: 3 | B8: Undefined | K8: Specific attributes are addressed to the documents to identify their applicabilty.
A9: 21 | B9: Undefined | K9: These attributes shall be used in combination with the filter function.
A10: 16 | B10: Undefined | K10: 2.1.1 Function
A11: 17 | B11: Undefined | K11: With the attribute Function documents are allocated to a specific function they describe and specify (e.g. EMC = Electromagnetic Compatibilty; AEB = Autonomous Emergency Braking, ... ).
A12: 25 | B12: Undefined | K12: The functions definitions and abbreviations are based on the ADASIS (Advanced Drivers Assistance Systems Interface Specifications) standard (see Appendix I).
A13: 19 | B13: Undefined | K13: In case the document does not address specific functions but specifies general requirements it will be marked as generic.
A14: 20 | B14: Undefined | K14: 2.1.2 Market Allocation
... A55: 367 | B55: Undefined | K55: Based on an international agreement (The Wassenaar Arrangement on Export Controls for Conventional Arms and Dual-Use Goods and Technologies) to contribute to regional and international security and stability by promoting transparency and greater responsibility in transfers of conventional arms and dual-use goods and technologies, thus preventing destabilizing accumulations. Participating states seek, through their national policies, to ensure that transfers of these items do not contribute to the development or enhancement of military capabilities which undermine these goals, and are not diverted to support such capabilities.
A56: 368 | B56: Undefined | C56: INTERNAL | D56: Transversal/ Generic | E56: Worldwide | F56: A | G56: Yes | H56: Covered by Valeo Process | J56: Export Control | K56: Product development and Export Control restriction | L56: GSI-RD-679 | M56: Mandatory Group Instruction This instruction presents the rules to be applied in order to master the Export Control restrictions of the products that we develop. | N56: A01 | Q56: no module available GSI-RD-679-A01_Product development and Export Control restriction | S56: GSI-RD-679 https://sites.google.com/a/valeo.com/group-procedures/group-procedures?filterM=GSI-RD-H01-0679 | T56: Export Control Assessment Questionnaire for Projects and Platforms | V56: Documentation (e.g. Datasheet; Drawing, FMEA,..) Covered by Platform/metiers Standards | W56: DU Classification and Approval
A57: 556 | B57: Undefined | C57: INTERNAL | D57: Transversal/ Generic | E57: Worldwide | F57: A | G57: Yes | H57: Covered by Valeo Process | J57: Export Control | K57: Export Controls of electronic parts | L57: GSI-RD-H01-0854 A03 | M57: Mandatory Group Instruction The purpose of this procedure is to describe the Valeo rules and processes applicable to detect and manage electronic parts that can be subject to Export Controls. It completes other procedures that are implemented at product levels. | N57: A03 | O57: 2023 | Q57: no module available | R57: https://docs.google.com/document/d/100OCp6Si8lebeB50uMYUcKSPxmOOM5ev3BsX4AHGNW8/edit#heading=h.3znysh7 | S57: GSI-RD-679 https://sites.google.com/a/valeo.com/group-procedures/group-procedures?filterM=GSI-RD-H01-0679 | T57: Export Control Assessment Questionnaire for Projects and Platforms | V57: Documentation (e.g. Datasheet; Drawing, FMEA,..) Covered by Platform/metiers Standards | W57: DU Classification and Approval
A58: 369 | B58: Undefined | C58: REGULATION | D58: Transversal/ Generic | E58: Europe | F58: A | G58: Yes | H58: Covered by Valeo Process | J58: Export Control | K58: (EU) 2021/821 | L58: Regulation (EU) 2021/821 of the European Parliament and of the Council of 20 May 2021 setting up a Union regime for the control of exports, brokering, technical assistance, transit and transfer of dual-use items | M58: This Regulation establishes a Union regime for the control of exports, brokering, technical assistance, transit and transfer of dual-use items. | N58: 45047 | S58: GSI-RD-679 https://sites.google.com/a/valeo.com/group-procedures/group-procedures?filterM=GSI-RD-H01-0679 | T58: Export Control Assessment Questionnaire for Projects and Platforms | V58: Documentation (e.g. Datasheet; Drawing, FMEA,..) Covered by Platform/metiers Standards | W58: DU Classification and Approval DU Classification and Approval
A59: 371 | B59: Undefined | C59: REGULATION | E59: USA | F59: A | G59: Yes | H59: Covered by Valeo Process | J59: Export Control | K59: De minimis Rules and Guidelines | L59: § 734.4 and Supplement No. 2 to part 734 of the EAR (as modified on 11 April 2018) | M59: Based on determined US content within the product the EAR are to be applied accordingly. | N59: 43191 | S59: GSI-RD-679 https://sites.google.com/a/valeo.com/group-procedures/group-procedures?filterM=GSI-RD-H01-0679 | T59: Export Control Assessment Questionnaire for Projects and Platforms | V59: Documentation (e.g. Datasheet; Drawing, FMEA,..) Covered by Platform/metiers Standards | W59: DU Classification and Approval
A60: 370 | B60: Undefined | C60: REGULATION | D60: Transversal/ Generic | E60: USA | F60: A | G60: Yes | H60: Covered by Valeo Process | J60: Export Control | K60: US Export Administration Regulation (EAR) | M60: Sections relevant: CCL3_Electronics CCL4_Computers CCL5_PT2_Information Security CCL6_Sensors and Lasers CCL7_Navigation and Avionics | N60: 2019-05-23 2018-10-29 2019-05-23 2019-05-23 2018-12-20 | R60: https://www.bis.doc.gov/index.php/regulations/export-administration-regulations-ear | S60: GSI-RD-679 https://sites.google.com/a/valeo.com/group-procedures/group-procedures?filterM=GSI-RD-H01-0679 | T60: Export Control Assessment Questionnaire for Projects and Platforms | V60: Documentation (e.g. Datasheet; Drawing, FMEA,..) Covered by Platform/metiers Standards | W60: DU Classification and Approval
A61: 226 | B61: Undefined | K61: 3.2 Radio & Laser Spectrum Matters
A62: 239 | B62: Undefined | K62: 3.2.1 Radio Regulations and Frequency Allocations
A63: 520 | B63: Undefined | C63: INTERNAL | D63: DRS - Radar | E63: Worldwide ITU Region 1 ITU Region 2 ITU Region 3 | F63: B | J63: Radio Emission | K63: World Wide Country List of Emission Limits for 77-81GHz | N63: 10.2022 | Q63: DRS_Radar_List of countries 77GHz_79GHz | V63: Product Marking Testing Documentation (e.g. Datasheet; Drawing, FMEA,..) Certification
A64: 319 | B64: Undefined | C64: REGULATION | D64: DRS - Radar | E64: ITU Region 3 | F64: B | J64: Radio Emission | K64: Infocomm Development Authority of Singapore | L64: RADIO SPECTRUM MASTER PLAN | M64: In Singapore, IDA as the telecommunication regulator, is charged with the responsibility of administering frequency management matters. The responsibility includes drawing up frequency allocation plans for various services, coordinating frequency assignments with neighbouring countries, monitoring spectrum usage and resolving radio interference. Annex 1 provides an overview of existing and planned services within the spectrum plan as well as the priority for review on an on-going basis. | N64: 41214 | Q64: 12146_SG_Master_Plan_Radio_Spectrum_2012-11_EN_2013-04-09 | R64: https://lis9-svdol10.vnet.valeo.com:1201/dwa/rm/urn:rational::1-43463251374b73b7-M-00081b51 | V64: Product Marking Testing Documentation (e.g. Datasheet; Drawing, FMEA,..) Certification
A65: 318 | B65: Undefined | C65: REGULATION | D65: DRS - Radar | E65: Taiwan ITU Region 3 | F65: B | J65: Radio Emission | K65: Telecom Technical Regulations Test Requirements | L65: Low-power Radio-frequency Devices Technical Regulations | M65: This regulation is formulated based on Section 1 of Article 50 of the Telecommunications Act. It consists of five chapters: Chapter 1 defines related terminology; Chapter 2 stipulates general requirements for the operating bands, radiated field intensity, performances and manufacture, installation, possession, import and sales of equipment. Low-power radio-frequency devices in this chapter are unrestricted unless otherwise stipulated by other laws codes; Chapter 3 and Chapter 4 outline specifications for conformity. As such these two chapters place limitations on the frequency bands and radiated field intensity and correspond to the relevant frequency bands and types of device. Those not stipulated in these two Chapters shall comply with the provisions of Chapter 2; Chapter 5 covers test requirements of type approvals on low-power radio-frequency devices. | N65: 43101 | Q65: 12147_2018-01-10_Taiwan_Low-power Radio-frequency Devices Technical Regulations | R65: https://lis9-svdol10.vnet.valeo.com:1201/dwa/rm/urn:rational::1-43463251374b73b7-M-00081b52 | V65: Product Marking Testing Documentation (e.g. Datasheet; Drawing, FMEA,..) Certification
A66: 142 | B66: Undefined | C66: REGULATION | D66: DRS - Radar ECU w WIFI/Bluetooth | E66: USA ITU Region 2 | F66: B | J66: Radio Emission | K66: Title 47 Chapter I Subchapter A Part 15 - Radio Frequency Devices | L66: Radio Frequency Devices | M66: (a) This part sets out the regulations under which an intentional, unintentional, or incidental radiator may be operated without an individual license. It also contains the technical specifications, administrative requirements and other conditions relating to the marketing of part 15 devices. (b) The operation of an intentional or unintentional radiator that is not in accordance with the regulations in this part must be licensed pursuant to the provisions of section 301 of the Communications Act of 1934, as amended, unless otherwise exempted from the licensing requirements elsewhere in this chapter. (c) Unless specifically exempted, the operation or marketing of an intentional or unintentional radiator that is ot in compliance with the administrative and technical provisions in this art, including prior Commission authorization or verification, as appropriate, is prohibited under section 302 f the Communications Act of 1934, as mended, and subpart I of part 2 of this chapter. The equipment authorization and verification procedures are detailed in subpart J of part 2 of this chapter. | N66: 42644 | Q66: 12121_FCC_Part15_Radio_frequency_Devices | R66: https://lis9-svdol10.vnet.valeo.com:1201/dwa/rm/urn:rational:67c31aaa-786d-11e4-943f-77f7170acf6c:1-43463251374b73b7-M-0006e53a | V66: Product Marking Testing Documentation (e.g. Datasheet; Drawing, FMEA,..) Certification
A67: 144 | B67: Undefined | C67: REGULATION | D67: DRS - Radar ECU w WIFI/Bluetooth | E67: USA ITU Region 2 | F67: A | J67: Radio Emission | K67: Title 47 §15.5 General conditions of operation | L67: §15.5 General conditions of operation | M67: (b) Operation of an intentional, unintentional, or incidental radiator is subject to the conditions that no harmful interference is caused and that interference must be accepted that may be caused by the operation of an authorized radio station, by another intentional or unintentional radiator, by industrial, scientific and medical (ISM) equipment, or by an incidental radiator. (c) The operator of a radio frequency device shall be required to cease operating the device upon notification by a Commission representative that the device is causing harmful interference. Operation shall not resume until the condition causing the harmful interference has been corrected. | N67: 42644 | R67: https://lis9-svdol10.vnet.valeo.com:1201/dwa/rm/urn:rational:67c31aaa-786d-11e4-943f-77f7170acf6c:1-43463251374b73b7-M-0006e53a | V67: Product Marking Testing Documentation (e.g. Datasheet; Drawing, FMEA,..) Certification
A68: 145 | B68: Undefined | C68: REGULATION | D68: DRS - Radar ECU w WIFI/Bluetooth | E68: USA ITU Region 2 | F68: A | J68: Radio Emission | K68: Title 47 §15.29 Inspection by the Commission | L68: §15.29 Inspection by the Commission | M68: Any equipment or device subject to the provisions of this part, together with any certificate, notice of registration or any technical data required to be kept on file by the operator, supplier or party responsible for compliance of the device shall be made available for inspection by a Commission representative upon reasonable request. | N68: 42644 | R68: https://lis9-svdol10.vnet.valeo.com:1201/dwa/rm/urn:rational:67c31aaa-786d-11e4-943f-77f7170acf6c:1-43463251374b73b7-M-0006e53a | V68: Product Marking Testing Documentation (e.g. Datasheet; Drawing, FMEA,..) Type Approval
A69: 143 | B69: Undefined | C69: REGULATION | D69: DRS - RLT DRS - ULS & ECU DVS - Vision System DVS - Viewing Camera DVS - ECU & Domain Controller DFC - Front Camera DRS - Solid State Lidar DRS - Laserscanner DFC - Zone Controller | E69: USA ITU Region 2 | F69: C | J69: EMC | K69: Title 47 §15.103 Exempted devices -- allocated devices do not need to apply FCC specific EMC requirements -- | L69: §15.103 Exempted devices | M69: The following devices are subject only to the general conditions of operation in §§15.5 and 15.29 and are exempt from the specific technical standards and other requirements contained in this part. ... Although not mandatory, it is strongly recommended that the manufacturer of an exempted device endeavor to have the device meet the specific technical standards in this part. (a) A digital device utilized exclusively in any transportation vehicle including motor vehicles and aircraft. | N69: 42644 | R69: https://lis9-svdol10.vnet.valeo.com:1201/dwa/rm/urn:rational:67c31aaa-786d-11e4-943f-77f7170acf6c:1-43463251374b73b7-M-0006e53a
A70: 199 | B70: Undefined | C70: REGULATION | D70: DRS - Radar ECU w WIFI/Bluetooth | E70: Europe ITU Region 1 | F70: C | J70: Radio Emission | K70: 2000/299/EC Classification of radio equipment | L70: 2000/299/EC: Commission Decision of 6 April 2000 establishing the initial classification of radio equipment and telecommunications terminal equipment and associated identifiers | M70: Definition of classes: Class 1: can be placed on the market and be put into service without restrictions Class 2: equipment where restrictians acc. to other legislations apply (e.g. Radio Equipment Directive) | N70: 36617 | O70: 36617 | Q70: - no module available - | R70: https://eur-lex.europa.eu/legal-content/EN/ALL/?uri=celex:32000D0299
A71: 190 | B71: Undefined | C71: REGULATION | D71: DRS - Radar ECU w WIFI/Bluetooth | E71: Europe ITU Region 1 | F71: B | J71: Radio Emission | K71: 2006/771/EC Radio Spectrum Short Range | L71: COMMISSION DECISION of 9 November 2006 on harmonisation of the radio spectrum for use by short-range devices | M71: The purpose of this Decision is to harmonise the frequency bands and the related technical parameters for the availability and efficient use of radio spectrum for short-range devices so that such devices may benefit from ‘Class 1’ classification under Commission Decision 2000/299/EC. | N71: 41609 | O71: 41883 | Q71: 12129_Decision 2006_771_EC_Radio Spectrum Short Range | R71: https://drive.google.com/file/d/1qPyPrxhVDzl2IQHg1kJES9F6-JvGe_aT/view | V71: Product Marking Testing Documentation (e.g. Datasheet; Drawing, FMEA,..)
A72: 65 | B72: Undefined | C72: REGULATION | D72: DRS - Radar ECU w WIFI/Bluetooth | E72: Europe ITU Region 1 | F72: B | J72: Radio Emission | K72: 2014/53/EU Radio Equipment Directive | L72: Directive 2014/53/EU of the European Parliament and of the Council of 16 April 2014 on the harmonisation of the laws of the Member States relating to the making available on the market of radio equipment and repealing Directive 1999/5/EC | M72: 1. This Directive establishes a regulatory framework for the making available on the market and putting into service in the Union of radio equipment. 2. This Directive shall not apply to equipment listed in Annex I. 3. This Directive shall not apply to radio equipment exclusively used for activities concerning public security, defence, State security, including the economic well-being of the State in the case of activities pertaining to State security matters, and the activities of the State in the area of criminal law. 4. Radio equipment falling within the scope of this Directive shall not be subject to Directive 2014/35/EU, except as set out in point (a) of Article 3(1) of this Directive. | N72: 41730 | O72: 42887 | Q72: 1216_Directive 2014-53-EU | R72: https://lis9-svdol10.vnet.valeo.com:1201/dwa/rm/urn:rational:67c31aaa-786d-11e4-943f-77f7170acf6c:1-43463251374b73b7-M-0006e525 | V72: Product Marking Testing Documentation (e.g. Datasheet; Drawing, FMEA,..)
A73: 69 | B73: Undefined | C73: GUIDELINE | D73: DRS - ULS & ECU DVS - Vision System DRS - Radar ECU w WIFI/Bluetooth | E73: Europe ITU Region 1 ITU Region 3 | F73: C | K73: Guide to the appl. of harmonised standards acc. directive 2014/53/EU | L73: Guide to the application of harmonised standards covering articles 3.1b and 3.2 of the Directive 2014/53/EU (RED) to multi-radio and combined radio and non-radio equipment | M73: The document provides guidance on the application of harmonised standards to multi-radio and combined equipment to demonstrate conformity with article 3.1b (EMC) and article 3.2 (effective and efficient use of the radio spectrum) of the Radio Equipment Directive (RED) i.1. | N73: 42522 | Q73: - no module available - | R73: http://www.etsi.org/deliver/etsi_eg/203300_203399/203367/01.01.01_60/eg_203367v010101p.pdf
A74: 240 | B74: Undefined | K74: 3.2.2 Short Range Radar 24 GHz Range
A75: 146 | B75: Undefined | C75: REGULATION | D75: DRS - Radar ECU w WIFI/Bluetooth | E75: USA ITU Region 2 | F75: B | J75: Radio Emission | K75: Title 47 §15.245 24 GHz range (24.075-24.175) | L75: Operation within the bands 902-928 MHz, 2435-2465 MHz, 5785-5815 MHz, 10500-10550 MHz, and 24075-24175 MHz | M75: 24 GHz range (24.075-24.175) | N75: 42644 | O75: 37865 | Q75: 12121_FCC_Part15_Radio_frequency_Devices | R75: https://lis9-svdol10.vnet.valeo.com:1201/dwa/rm/urn:rational:67c31aaa-786d-11e4-943f-77f7170acf6c:1-43463251374b73b7-M-0006e53a | V75: Testing Documentation (e.g. Datasheet; Drawing, FMEA,..)
A76: 147 | B76: Undefined | C76: REGULATION | D76: DRS - Radar ECU w WIFI/Bluetooth | E76: USA ITU Region 2 | F76: B | J76: Radio Emission | K76: Title 47 §15.249 24 GHz range (24.0-24.25) | L76: Operation within the bands 902-928 MHz, 2400-2483.5 MHz, 5725-5875 MHZ, and 24.0-24.25 GHz | M76: 24 GHz range (24.0-24.25) | N76: 42644 | O76: 40940 | Q76: 12121_FCC_Part15_Radio_frequency_Devices | R76: https://lis9-svdol10.vnet.valeo.com:1201/dwa/rm/urn:rational:67c31aaa-786d-11e4-943f-77f7170acf6c:1-43463251374b73b7-M-0006e53a | V76: Testing Documentation (e.g. Datasheet; Drawing, FMEA,..)
A77: 189 | B77: Undefined | C77: REGULATION | D77: DRS - Radar ECU w WIFI/Bluetooth | E77: Europe ITU Region 1 | F77: B | J77: Radio Emission | K77: 2005/50/EC 24GHz Range 24,15 +/– 2,50 GHz | L77: COMMISSION DECISION of 17 January 2005 on the harmonisation of the 24 GHz range radio spectrum band for the time-limited use by automotive short-range radar equipment in the Community | M77: The purpose of this Decision is to harmonise the conditions for the availability and efficient use of the 24 GHz range radio spectrum band for automotive short-range radar equipment. | N77: 43040 | O77: 43040 | Q77: 12139_Decision 2005_50_EC_24GHz_Range | R77: https://drive.google.com/file/d/1sjAs9WDwGIgzJQ1bCfBv5SEAmcKaE6Td/view | V77: Testing Documentation (e.g. Datasheet; Drawing, FMEA,..)
A78: 188 | B78: Undefined | C78: REGULATION | D78: DRS - Radar ECU w WIFI/Bluetooth | E78: Europe ITU Region 1 | F78: B | J78: Radio Emission | K78: 2013/752/EU Radio Spectrum amending 2006/771/EC | L78: COMMISSION IMPLEMENTING DECISION of 11 December 2013 amending Decision 2006/771/EC on harmonisation of the radio spectrum for use by short-range devices and repealing Decision 2005/928/EC | M78: Commission Decision 2006/771/EC (2) harmonises the technical conditions for use of spectrum for a wide variety of short-range devices, including applications such as alarms, local communications equipment, door openers, medical implants and for intelligent transport systems. Short-range devices are typically mass-market and/or portable products which can easily be taken and used across borders; | N78: 41609 | O78: 41883 | Q78: - no module available - | R78: https://drive.google.com/file/d/1NzU-kyRtgXUPqSEdGtw9gpl7Bxgk3dbn/view | V78: Testing Documentation (e.g. Datasheet; Drawing, FMEA,..)
A79: 241 | B79: Undefined | K79: 3.2.3 Short Range Radar 79 GHz Range
A80: 148 | B80: Undefined | C80: REGULATION | D80: DRS - Radar ECU w WIFI/Bluetooth | E80: USA ITU Region 2 | F80: B | J80: Radio Emission | K80: Title 47 §95 76-81 GHz range | L80: Subpart M The 76–81 GHz Band Radar Service | M80: This subpart sets out the regulations that apply to radar systems operating in the 76–81 GHz band. This subpart does not apply to Level Probing Radars that operate under part 15 of this title. | O80: 43009 | Q80: 12150_CFR 47 Part95 Subpart M_76-81 GHz Band Radar Service | R80: https://lis9-svdol10.vnet.valeo.com:1201/dwa/rm/urn:rational:67c31aaa-786d-11e4-943f-77f7170acf6c:1-43463251374b73b7-M-0006e535 | V80: Testing Documentation (e.g. Datasheet; Drawing, FMEA,..)
A81: 195 | B81: Undefined | C81: REGULATION | D81: DRS - Radar ECU w WIFI/Bluetooth | E81: Europe ITU Region 1 | F81: B | J81: Radio Emission | K81: 2004/545/EC 79GHz range 77-81 GHz | L81: COMMISSION DECISION of 8 July 2004 on the harmonisation of radio spectrum in the 79 GHz range for the use of automotive short-range radar equipment in the Community | M81: The purpose of this Decision is to harmonise the conditions for the availability and efficient use of the 79 GHz range radio spectrum band for automotive short-range radar equipment. "Article 3 The maximum mean power density shall be of – 3 dBm/MHz effective isotropic radiated power (e.i.r.p.) associated with a peak limit of 55 dBm e.i.r.p. The maximum mean power density outside a vehicle resulting from the operation of one short-range radar shall not exceed – 9 dBm/MHz e.i.r.p." | N81: 38139 | O81: 38139 | Q81: 12156_Decision_2004_545_EC_79GHz range | R81: https://lis9-svdol10.vnet.valeo.com:1201/dwa/rm/urn:rational::1-43463251374b73b7-M-00081b5b | V81: Testing Documentation (e.g. Datasheet; Drawing, FMEA,..)
...

Sheet Doc Overview
A1: m | C1: Regulations, norms and standards for DOORS transfer
Q2: GDRIVE | R2: AUREON | W2: ='CDV2 DTL'!A1 -> 14.08.2025 | X2: 03.03.2023 | AC2: Transversal | AD2: DVS System | AG2: DSW_Computer Vision | AJ2: DVS_Camera | AM2: Domain Controller/ECU (purly HW&Mechtronik) | AP2: DRS_RLT | AS2: DRS_ULS&ECU | AV2: DRS_Radar | AY2: DAS-Laser | BB2: DFC (Zone Controller) | BE2: DFC (Front Camera) | BH2: DSF_ADSP | BK2: DSF LSMS | BN2: Comment Status | BO2: Info
A3: Entry Date | B3: ID | C3: Item | D3: Priority | E3: Transfer Status | F3: Official Title/ Regulation Number | G3: Sub Title | H3: Scope | I3: Change information | J3: EU/GSR ADAS Marker | K3: Details | L3: Amendment Level | M3: Official Publication Date | N3: Legal Enforcement | O3: Vehicle Cat. | P3: Market | Q3: Document | R3: Aureon Link | S3: Pages | T3: Type of DOC: | U3: Module Name | V3: CDV1 | W3: CDV2 entered | X3: CDV 3 entered | Y3: Status | Z3: Comment Status | AA3: Plattform Allocation | AB3: Analyses/ Matrix | AC3: GENERIC | AD3: Applicable | AE3: deployed? | AF3: Responsible Expert | AG3: Applicable | AH3: deployed? | AI3: Responsible Expert | AJ3: Applicable | AK3: deployed? | AL3: Responsible Expert | AM3: Applicable | AN3: deployed?/ listed in TT metrics | AO3: Responsible Expert | AP3: Applicable | AQ3: deployed? | AR3: Responsible Expert | AS3: Applicable | AT3: deployed? | AU3: Responsible Expert | AV3: Applicable | AW3: deployed? | AX3: Responsible Expert | AY3: Applicable | AZ3: deployed? | BA3: Responsible Expert | BB3: Applicable | BC3: deployed? | BD3: Responsible Expert | BE3: Applicable | BF3: deployed? | BG3: Responsible Expert | BH3: Applicable | BI3: deployed? | BJ3: Responsible Expert | BK3: Applicable | BL3: deployed? | BM3: Responsible Expert
B4: REG_5 | C4: 1 | D4: high | E4: 10/10: Closed | H4: =VLOOKUP(U4,'CDV3 DTL'!E:G,2,FALSE) -> #N/A | O4: all | P4: UN | Q4: =HYPERLINK("https://drive.google.com/open?id=1jO2NDa-5_qi9OJp5wCn7zaV6xchAb5Uy","UN ECE R46_Devices for Indirect Vision Rev6") -> UN ECE R46_Devices for Indirect Vision Rev6 | S4: 90 | T4: Regulations | U4: 1205_ECE_R046 | W4: =IF(VLOOKUP(U4,'CDV2 DTL'!P:P,1,FALSE)=U4,"OK","Missing") -> OK | X4: =IF(VLOOKUP(U4,'CDV3 DTL'!E:E,1,FALSE)=U4,"OK","Missing") -> #N/A | AD4: x | AE4: =IF(AD4="x",VLOOKUP($U4,DVS!A:A,1,FALSE),"-") -> #N/A | AJ4: x | AN4: =IF(AM4="x",VLOOKUP($U4,'Domain ControllerECU'!A:A,1,FALSE),"-") -> - | AQ4: =IF(AP4="x",VLOOKUP($U4,RLT!A:A,1,FALSE),"-") -> - | AT4: =IF(AS4="x",VLOOKUP($U4,ULSECU!A:A,1,FALSE),"-") -> - | AW4: =IF(AV4="x",VLOOKUP($U4,'Radar 7779GHz'!A:A,1,FALSE),"-") -> - | AZ4: =IF(AY4="x",VLOOKUP($U4,LiDAR!A:A,1,FALSE),"-") -> - | BF4: =IF(BE4="x",VLOOKUP($U4,DFC!A:A,1,FALSE),"-") -> - | BI4: =IF(BH4="x",VLOOKUP(U4,'DSF ADSP'!A:A,1,FALSE),"-") -> - | BL4: =IF(BK4="x",VLOOKUP($U4,'DSF LSMS'!$A:$A,1,FALSE),"-") -> -
B5: REG_55 | C5: 2 | D5: normal | E5: Obsolete | H5: =VLOOKUP(U5,'CDV3 DTL'!E:G,2,FALSE) -> #N/A | P5: UN | Q5: =HYPERLINK("https://drive.google.com/open?id=1QOugWYCegJDbTpPi2fK5Sg6T0O0rPEba","UN ECE R10_EMC") -> UN ECE R10_EMC | S5: 140 | T5: Regulations | U5: (-) | W5: =IF(VLOOKUP(U5,'CDV2 DTL'!P:P,1,FALSE)=U5,"OK","Missing") -> #N/A | X5: =IF(VLOOKUP(U5,'CDV3 DTL'!E:E,1,FALSE)=U5,"OK","Missing") -> #N/A | AE5: =IF(AD5="x",VLOOKUP($U5,DVS!A:A,1,FALSE),"-") -> - | AN5: =IF(AM5="x",VLOOKUP($U5,'Domain ControllerECU'!A:A,1,FALSE),"-") -> - | AQ5: =IF(AP5="x",VLOOKUP($U5,RLT!A:A,1,FALSE),"-") -> - | AT5: =IF(AS5="x",VLOOKUP($U5,ULSECU!A:A,1,FALSE),"-") -> - | AW5: =IF(AV5="x",VLOOKUP($U5,'Radar 7779GHz'!A:A,1,FALSE),"-") -> - | AZ5: =IF(AY5="x",VLOOKUP($U5,LiDAR!A:A,1,FALSE),"-") -> - | BF5: =IF(BE5="x",VLOOKUP($U5,DFC!A:A,1,FALSE),"-") -> - | BI5: =IF(BH5="x",VLOOKUP(U5,'DSF ADSP'!A:A,1,FALSE),"-") -> - | BL5: =IF(BK5="x",VLOOKUP($U5,'DSF LSMS'!$A:$A,1,FALSE),"-") -> -
B6: REG_62 | C6: 3 | D6: low | E6: Obsolete | H6: =VLOOKUP(U6,'CDV3 DTL'!E:G,2,FALSE) -> #N/A | P6: EU | Q6: ETSI EN 301 091-1 V2.1.1 | S6: 18 | T6: HN-Std | U6: (-) | W6: =IF(VLOOKUP(U6,'CDV2 DTL'!P:P,1,FALSE)=U6,"OK","Missing") -> #N/A | X6: =IF(VLOOKUP(U6,'CDV3 DTL'!E:E,1,FALSE)=U6,"OK","Missing") -> #N/A | AE6: =IF(AD6="x",VLOOKUP($U6,DVS!A:A,1,FALSE),"-") -> - | AN6: =IF(AM6="x",VLOOKUP($U6,'Domain ControllerECU'!A:A,1,FALSE),"-") -> - | AQ6: =IF(AP6="x",VLOOKUP($U6,RLT!A:A,1,FALSE),"-") -> - | AT6: =IF(AS6="x",VLOOKUP($U6,ULSECU!A:A,1,FALSE),"-") -> - | AV6: x | AW6: =IF(AV6="x",VLOOKUP($U6,'Radar 7779GHz'!A:A,1,FALSE),"-") -> #N/A | AZ6: =IF(AY6="x",VLOOKUP($U6,LiDAR!A:A,1,FALSE),"-") -> - | BF6: =IF(BE6="x",VLOOKUP($U6,DFC!A:A,1,FALSE),"-") -> - | BI6: =IF(BH6="x",VLOOKUP(U6,'DSF ADSP'!A:A,1,FALSE),"-") -> - | BL6: =IF(BK6="x",VLOOKUP($U6,'DSF LSMS'!$A:$A,1,FALSE),"-") -> -
B7: REG_68 | C7: 4 | D7: high | E7: 10/10: Closed | H7: =VLOOKUP(U7,'CDV3 DTL'!E:G,2,FALSE) -> #N/A | O7: all | P7: UN | Q7: =HYPERLINK("https://drive.google.com/open?id=1DlHEwJ8yZ1ogHpl0J_JCfQ9Rsq2ueyvV","UN ECE R48_Light&Signaling") -> UN ECE R48_Light&Signaling | S7: 131 | T7: Regulations | U7: 1268_UN ECE R48_Light_Signaling | W7: =IF(VLOOKUP(U7,'CDV2 DTL'!P:P,1,FALSE)=U7,"OK","Missing") -> #N/A | X7: =IF(VLOOKUP(U7,'CDV3 DTL'!E:E,1,FALSE)=U7,"OK","Missing") -> #N/A | AE7: =IF(AD7="x",VLOOKUP($U7,DVS!A:A,1,FALSE),"-") -> - | AN7: =IF(AM7="x",VLOOKUP($U7,'Domain ControllerECU'!A:A,1,FALSE),"-") -> - | AP7: x | AQ7: =IF(AP7="x",VLOOKUP($U7,RLT!A:A,1,FALSE),"-") -> #N/A | AT7: =IF(AS7="x",VLOOKUP($U7,ULSECU!A:A,1,FALSE),"-") -> - | AW7: =IF(AV7="x",VLOOKUP($U7,'Radar 7779GHz'!A:A,1,FALSE),"-") -> - | AZ7: =IF(AY7="x",VLOOKUP($U7,LiDAR!A:A,1,FALSE),"-") -> - | BE7: x | BF7: =IF(BE7="x",VLOOKUP($U7,DFC!A:A,1,FALSE),"-") -> #N/A | BI7: =IF(BH7="x",VLOOKUP(U7,'DSF ADSP'!A:A,1,FALSE),"-") -> - | BL7: =IF(BK7="x",VLOOKUP($U7,'DSF LSMS'!$A:$A,1,FALSE),"-") -> -
B8: REG_86 | C8: 5 | D8: low | E8: 10/10: Closed | H8: =VLOOKUP(U8,'CDV3 DTL'!E:G,2,FALSE) -> #N/A | P8: EU | Q8: =HYPERLINK("https://drive.google.com/open?id=1RvzHOhWplUUiBHJr2H1-ReL0h44JniRM","2014/30/EU_EMC") -> 2014/30/EU_EMC | S8: 28 | T8: Regulations | U8: 1286_2014-30-EU_EMC | W8: =IF(VLOOKUP(U8,'CDV2 DTL'!P:P,1,FALSE)=U8,"OK","Missing") -> OK | X8: =IF(VLOOKUP(U8,'CDV3 DTL'!E:E,1,FALSE)=U8,"OK","Missing") -> #N/A | AE8: =IF(AD8="x",VLOOKUP($U8,DVS!A:A,1,FALSE),"-") -> - | AN8: =IF(AM8="x",VLOOKUP($U8,'Domain ControllerECU'!A:A,1,FALSE),"-") -> - | AQ8: =IF(AP8="x",VLOOKUP($U8,RLT!A:A,1,FALSE),"-") -> - | AT8: =IF(AS8="x",VLOOKUP($U8,ULSECU!A:A,1,FALSE),"-") -> - | AW8: =IF(AV8="x",VLOOKUP($U8,'Radar 7779GHz'!A:A,1,FALSE),"-") -> - | AZ8: =IF(AY8="x",VLOOKUP($U8,LiDAR!A:A,1,FALSE),"-") -> - | BF8: =IF(BE8="x",VLOOKUP($U8,DFC!A:A,1,FALSE)," ") | BI8: =IF(BH8="x",VLOOKUP(U8,'DSF ADSP'!A:A,1,FALSE),"-") -> - | BL8: =IF(BK8="x",VLOOKUP($U8,'DSF LSMS'!$A:$A,1,FALSE),"-") -> -
B9: REG_88 | C9: 6 | D9: low | E9: Obsolete | H9: =VLOOKUP(U9,'CDV3 DTL'!E:G,2,FALSE) -> #N/A | P9: EU | Q9: ETSI EN 302 264 V2.1.1 | S9: 17 | T9: HN-Std | U9: (-) | W9: =IF(VLOOKUP(U9,'CDV2 DTL'!P:P,1,FALSE)=U9,"OK","Missing") -> #N/A | X9: =IF(VLOOKUP(U9,'CDV3 DTL'!E:E,1,FALSE)=U9,"OK","Missing") -> #N/A | AE9: =IF(AD9="x",VLOOKUP($U9,DVS!A:A,1,FALSE),"-") -> - | AN9: =IF(AM9="x",VLOOKUP($U9,'Domain ControllerECU'!A:A,1,FALSE),"-") -> - | AQ9: =IF(AP9="x",VLOOKUP($U9,RLT!A:A,1,FALSE),"-") -> - | AT9: =IF(AS9="x",VLOOKUP($U9,ULSECU!A:A,1,FALSE),"-") -> - | AV9: x | AW9: =IF(AV9="x",VLOOKUP($U9,'Radar 7779GHz'!A:A,1,FALSE),"-") -> #N/A | AZ9: =IF(AY9="x",VLOOKUP($U9,LiDAR!A:A,1,FALSE),"-") -> - | BF9: =IF(BE9="x",VLOOKUP($U9,DFC!A:A,1,FALSE),"-") -> - | BI9: =IF(BH9="x",VLOOKUP(U9,'DSF ADSP'!A:A,1,FALSE),"-") -> - | BL9: =IF(BK9="x",VLOOKUP($U9,'DSF LSMS'!$A:$A,1,FALSE),"-") -> -
B10: REG_89 | C10: 7 | D10: low | E10: 10/10: Closed | H10: =VLOOKUP(U10,'CDV3 DTL'!E:G,2,FALSE) -> #N/A | P10: EU | Q10: =HYPERLINK("https://drive.google.com/open?id=1fC1zpmhiQ9jxEyqhVR-AbvhsINmXYOYI","2014/35/EU_LowVoltage") -> 2014/35/EU_LowVoltage | S10: 18 | T10: Regulations | U10: 1289_2014_34_EU_LowVoltage | W10: =IF(VLOOKUP(U10,'CDV2 DTL'!P:P,1,FALSE)=U10,"OK","Missing") -> OK | X10: =IF(VLOOKUP(U10,'CDV3 DTL'!E:E,1,FALSE)=U10,"OK","Missing") -> #N/A | AE10: =IF(AD10="x",VLOOKUP($U10,DVS!A:A,1,FALSE),"-") -> - | AN10: =IF(AM10="x",VLOOKUP($U10,'Domain ControllerECU'!A:A,1,FALSE),"-") -> - | AQ10: =IF(AP10="x",VLOOKUP($U10,RLT!A:A,1,FALSE),"-") -> - | AT10: =IF(AS10="x",VLOOKUP($U10,ULSECU!A:A,1,FALSE),"-") -> - | AW10: =IF(AV10="x",VLOOKUP($U10,'Radar 7779GHz'!A:A,1,FALSE),"-") -> - | AZ10: =IF(AY10="x",VLOOKUP($U10,LiDAR!A:A,1,FALSE),"-") -> - | BF10: =IF(BE10="x",VLOOKUP($U10,DFC!A:A,1,FALSE),"-") -> - | BI10: =IF(BH10="x",VLOOKUP(U10,'DSF ADSP'!A:A,1,FALSE),"-") -> - | BL10: =IF(BK10="x",VLOOKUP($U10,'DSF LSMS'!$A:$A,1,FALSE),"-") -> -
B11: REG_90 | C11: 8 | D11: low | E11: 10/10: Closed | H11: =VLOOKUP(U11,'CDV3 DTL'!E:G,2,FALSE) -> #N/A | K11: Annex 8 for safety assessment, to be applied if breaking function is not related to AEB | O11: all | P11: UN | Q11: =HYPERLINK("https://drive.google.com/open?id=1VuiQ3S3nKkfKCPEmNCSu-7QjNbIVSaSe","UN ECE R13_Braking") -> UN ECE R13_Braking | S11: 97 | T11: Regulations | U11: 1290_UN ECE R13_Braking | W11: =IF(VLOOKUP(U11,'CDV2 DTL'!P:P,1,FALSE)=U11,"OK","Missing") -> OK | X11: =IF(VLOOKUP(U11,'CDV3 DTL'!E:E,1,FALSE)=U11,"OK","Missing") -> #N/A | AA11: DSF | AD11: X | AE11: =IF(AD11="x",VLOOKUP($U11,DVS!A:A,1,FALSE),"-") -> #N/A | AN11: =IF(AM11="x",VLOOKUP($U11,'Domain ControllerECU'!A:A,1,FALSE),"-") -> - | AQ11: =IF(AP11="x",VLOOKUP($U11,RLT!A:A,1,FALSE),"-") -> - | AT11: =IF(AS11="x",VLOOKUP($U11,ULSECU!A:A,1,FALSE),"-") -> - | AW11: =IF(AV11="x",VLOOKUP($U11,'Radar 7779GHz'!A:A,1,FALSE),"-") -> - | AZ11: =IF(AY11="x",VLOOKUP($U11,LiDAR!A:A,1,FALSE),"-") -> - | BE11: x | BF11: =IF(BE11="x",VLOOKUP($U11,DFC!A:A,1,FALSE),"-") -> #N/A | BH11: x | BI11: =IF(BH11="x",VLOOKUP(U11,'DSF ADSP'!A:A,1,FALSE),"-") -> #N/A | BK11: x | BL11: =IF(BK11="x",VLOOKUP($U11,'DSF LSMS'!$A:$A,1,FALSE),"-") -> #N/A | BM11: DSF LSMS Braking Team akram.ghadieh@valeo.com
B12: REG_91 | C12: 9 | D12: low | E12: Obsolete | H12: =VLOOKUP(U12,'CDV3 DTL'!E:G,2,FALSE) -> #N/A | P12: China | Q12: =HYPERLINK("https://drive.google.com/open?id=1vRlOc7Za6XRNeLV4n9mkTkxmGaSo2nDa","GB/T 18655-2010") -> GB/T 18655-2010 | S12: 136 | T12: Standard | U12: (-) | W12: =IF(VLOOKUP(U12,'CDV2 DTL'!P:P,1,FALSE)=U12,"OK","Missing") -> #N/A | X12: =IF(VLOOKUP(U12,'CDV3 DTL'!E:E,1,FALSE)=U12,"OK","Missing") -> #N/A | AE12: =IF(AD12="x",VLOOKUP($U12,DVS!A:A,1,FALSE),"-") -> - | AN12: =IF(AM12="x",VLOOKUP($U12,'Domain ControllerECU'!A:A,1,FALSE),"-") -> - | AQ12: =IF(AP12="x",VLOOKUP($U12,RLT!A:A,1,FALSE),"-") -> - | AT12: =IF(AS12="x",VLOOKUP($U12,ULSECU!A:A,1,FALSE),"-") -> - | AW12: =IF(AV12="x",VLOOKUP($U12,'Radar 7779GHz'!A:A,1,FALSE),"-") -> - | AZ12: =IF(AY12="x",VLOOKUP($U12,LiDAR!A:A,1,FALSE),"-") -> - | BF12: =IF(BE12="x",VLOOKUP($U12,DFC!A:A,1,FALSE),"-") -> - | BI12: =IF(BH12="x",VLOOKUP(U12,'DSF ADSP'!A:A,1,FALSE),"-") -> - | BL12: =IF(BK12="x",VLOOKUP($U12,'DSF LSMS'!$A:$A,1,FALSE),"-") -> -
B13: REG_92 | C13: 10 | D13: low | E13: Obsolete | H13: =VLOOKUP(U13,'CDV3 DTL'!E:G,2,FALSE) -> #N/A | P13: EU | Q13: =HYPERLINK("https://drive.google.com/open?id=1BtYMnrBX3F77DDYbynUSu4GCbPcTpSjJ","REGULATION (EC) No 78/2009") -> REGULATION (EC) No 78/2009 | S13: 38 | T13: Regulations | U13: (-) | W13: =IF(VLOOKUP(U13,'CDV2 DTL'!P:P,1,FALSE)=U13,"OK","Missing") -> #N/A | X13: =IF(VLOOKUP(U13,'CDV3 DTL'!E:E,1,FALSE)=U13,"OK","Missing") -> #N/A | AE13: =IF(AD13="x",VLOOKUP($U13,DVS!A:A,1,FALSE),"-") -> - | AN13: =IF(AM13="x",VLOOKUP($U13,'Domain ControllerECU'!A:A,1,FALSE),"-") -> - | AQ13: =IF(AP13="x",VLOOKUP($U13,RLT!A:A,1,FALSE),"-") -> - | AT13: =IF(AS13="x",VLOOKUP($U13,ULSECU!A:A,1,FALSE),"-") -> - | AV13: x | AW13: =IF(AV13="x",VLOOKUP($U13,'Radar 7779GHz'!A:A,1,FALSE),"-") -> #N/A | AZ13: =IF(AY13="x",VLOOKUP($U13,LiDAR!A:A,1,FALSE),"-") -> - | BF13: =IF(BE13="x",VLOOKUP($U13,DFC!A:A,1,FALSE),"-") -> - | BI13: =IF(BH13="x",VLOOKUP(U13,'DSF ADSP'!A:A,1,FALSE),"-") -> - | BL13: =IF(BK13="x",VLOOKUP($U13,'DSF LSMS'!$A:$A,1,FALSE),"-") -> -
B14: REG_93 | C14: 11 | D14: low | E14: 10/10: Closed | H14: =VLOOKUP(U14,'CDV3 DTL'!E:G,2,FALSE) -> #N/A | P14: EU | Q14: =HYPERLINK("https://drive.google.com/open?id=1NzU-kyRtgXUPqSEdGtw9gpl7Bxgk3dbn","Decision 2013/752/EU_ Radio Spectrum") -> Decision 2013/752/EU_ Radio Spectrum | S14: 20 | T14: Regulations | U14: 12146_SG_Master_Plan_Radio_Spectrum_2012-11_EN_2013-04-09 | W14: =IF(VLOOKUP(U14,'CDV2 DTL'!P:P,1,FALSE)=U14,"OK","Missing") -> OK | X14: =IF(VLOOKUP(U14,'CDV3 DTL'!E:E,1,FALSE)=U14,"OK","Missing") -> #N/A | AE14: =IF(AD14="x",VLOOKUP($U14,DVS!A:A,1,FALSE),"-") -> - | AN14: =IF(AM14="x",VLOOKUP($U14,'Domain ControllerECU'!A:A,1,FALSE),"-") -> - | AQ14: =IF(AP14="x",VLOOKUP($U14,RLT!A:A,1,FALSE),"-") -> - | AT14: =IF(AS14="x",VLOOKUP($U14,ULSECU!A:A,1,FALSE),"-") -> - | AV14: x | AW14: =IF(AV14="x",VLOOKUP($U14,'Radar 7779GHz'!A:A,1,FALSE),"-") -> #N/A | AZ14: =IF(AY14="x",VLOOKUP($U14,LiDAR!A:A,1,FALSE),"-") -> - | BF14: =IF(BE14="x",VLOOKUP($U14,DFC!A:A,1,FALSE),"-") -> - | BI14: =IF(BH14="x",VLOOKUP(U14,'DSF ADSP'!A:A,1,FALSE),"-") -> - | BL14: =IF(BK14="x",VLOOKUP($U14,'DSF LSMS'!$A:$A,1,FALSE),"-") -> -
